[2025-09-20T19:52:45.142+0000] {local_task_job_runner.py:123} INFO - ::group::Pre task execution logs
[2025-09-20T19:52:45.223+0000] {taskinstance.py:2612} INFO - Dependencies all met for dep_context=non-requeueable deps ti=<TaskInstance: generate_orders_dag.generate_orders scheduled__2025-09-20T19:45:00+00:00 [queued]>
[2025-09-20T19:52:45.232+0000] {taskinstance.py:2612} INFO - Dependencies all met for dep_context=requeueable deps ti=<TaskInstance: generate_orders_dag.generate_orders scheduled__2025-09-20T19:45:00+00:00 [queued]>
[2025-09-20T19:52:45.234+0000] {taskinstance.py:2865} INFO - Starting attempt 1 of 1
[2025-09-20T19:52:45.248+0000] {taskinstance.py:2888} INFO - Executing <Task(PythonOperator): generate_orders> on 2025-09-20 19:45:00+00:00
[2025-09-20T19:52:45.255+0000] {standard_task_runner.py:72} INFO - Started process 144 to run task
[2025-09-20T19:52:45.258+0000] {standard_task_runner.py:104} INFO - Running: ['airflow', 'tasks', 'run', 'generate_orders_dag', 'generate_orders', 'scheduled__2025-09-20T19:45:00+00:00', '--job-id', '26', '--raw', '--subdir', 'DAGS_FOLDER/generate_orders_dag.py', '--cfg-path', '/tmp/tmplyrsqket']
[2025-09-20T19:52:45.262+0000] {standard_task_runner.py:105} INFO - Job 26: Subtask generate_orders
[2025-09-20T19:52:45.362+0000] {task_command.py:467} INFO - Running <TaskInstance: generate_orders_dag.generate_orders scheduled__2025-09-20T19:45:00+00:00 [running]> on host 48ee850a336d
[2025-09-20T19:52:45.460+0000] {taskinstance.py:3131} INFO - Exporting env vars: AIRFLOW_CTX_DAG_OWNER='airflow' AIRFLOW_CTX_DAG_ID='generate_orders_dag' AIRFLOW_CTX_TASK_ID='generate_orders' AIRFLOW_CTX_EXECUTION_DATE='2025-09-20T19:45:00+00:00' AIRFLOW_CTX_TRY_NUMBER='1' AIRFLOW_CTX_DAG_RUN_ID='scheduled__2025-09-20T19:45:00+00:00'
[2025-09-20T19:52:45.463+0000] {taskinstance.py:731} INFO - ::endgroup::
[2025-09-20T19:52:45.553+0000] {taskinstance.py:3310} ERROR - Task failed with exception
Traceback (most recent call last):
  File "/home/airflow/.local/lib/python3.12/site-packages/airflow/models/taskinstance.py", line 767, in _execute_task
    result = _execute_callable(context=context, **execute_callable_kwargs)
             ^^^^^^^^^^^^^^^^^^^^^^^^^^^^^^^^^^^^^^^^^^^^^^^^^^^^^^^^^^^^^
  File "/home/airflow/.local/lib/python3.12/site-packages/airflow/models/taskinstance.py", line 733, in _execute_callable
    return ExecutionCallableRunner(
           ^^^^^^^^^^^^^^^^^^^^^^^^
  File "/home/airflow/.local/lib/python3.12/site-packages/airflow/utils/operator_helpers.py", line 252, in run
    return self.func(*args, **kwargs)
           ^^^^^^^^^^^^^^^^^^^^^^^^^^
  File "/home/airflow/.local/lib/python3.12/site-packages/airflow/models/baseoperator.py", line 406, in wrapper
    return func(self, *args, **kwargs)
           ^^^^^^^^^^^^^^^^^^^^^^^^^^^
  File "/home/airflow/.local/lib/python3.12/site-packages/airflow/operators/python.py", line 238, in execute
    return_value = self.execute_callable()
                   ^^^^^^^^^^^^^^^^^^^^^^^
  File "/home/airflow/.local/lib/python3.12/site-packages/airflow/operators/python.py", line 256, in execute_callable
    return runner.run(*self.op_args, **self.op_kwargs)
           ^^^^^^^^^^^^^^^^^^^^^^^^^^^^^^^^^^^^^^^^^^^
  File "/home/airflow/.local/lib/python3.12/site-packages/airflow/utils/operator_helpers.py", line 252, in run
    return self.func(*args, **kwargs)
           ^^^^^^^^^^^^^^^^^^^^^^^^^^
  File "/opt/airflow/dags/generate_orders_dag.py", line 32, in generate_orders
    cur.execute("SELECT id FROM clean.users;")
psycopg2.errors.UndefinedTable: ОШИБКА:  отношение "clean.users" не существует
LINE 1: SELECT id FROM clean.users;
                       ^

[2025-09-20T19:52:45.573+0000] {taskinstance.py:1225} INFO - Marking task as FAILED. dag_id=generate_orders_dag, task_id=generate_orders, run_id=scheduled__2025-09-20T19:45:00+00:00, execution_date=20250920T194500, start_date=20250920T195245, end_date=20250920T195245
[2025-09-20T19:52:45.587+0000] {taskinstance.py:340} INFO - ::group::Post task execution logs
[2025-09-20T19:52:45.589+0000] {standard_task_runner.py:124} ERROR - Failed to execute job 26 for task generate_orders (ОШИБКА:  отношение "clean.users" не существует
LINE 1: SELECT id FROM clean.users;
                       ^
; 144)
Traceback (most recent call last):
  File "/home/airflow/.local/lib/python3.12/site-packages/airflow/task/task_runner/standard_task_runner.py", line 117, in _start_by_fork
    ret = args.func(args, dag=self.dag)
          ^^^^^^^^^^^^^^^^^^^^^^^^^^^^^
  File "/home/airflow/.local/lib/python3.12/site-packages/airflow/cli/cli_config.py", line 49, in command
    return func(*args, **kwargs)
           ^^^^^^^^^^^^^^^^^^^^^
  File "/home/airflow/.local/lib/python3.12/site-packages/airflow/utils/cli.py", line 115, in wrapper
    return f(*args, **kwargs)
           ^^^^^^^^^^^^^^^^^^
  File "/home/airflow/.local/lib/python3.12/site-packages/airflow/cli/commands/task_command.py", line 483, in task_run
    task_return_code = _run_task_by_selected_method(args, _dag, ti)
                       ^^^^^^^^^^^^^^^^^^^^^^^^^^^^^^^^^^^^^^^^^^^^
  File "/home/airflow/.local/lib/python3.12/site-packages/airflow/cli/commands/task_command.py", line 256, in _run_task_by_selected_method
    return _run_raw_task(args, ti)
           ^^^^^^^^^^^^^^^^^^^^^^^
  File "/home/airflow/.local/lib/python3.12/site-packages/airflow/cli/commands/task_command.py", line 341, in _run_raw_task
    return ti._run_raw_task(
           ^^^^^^^^^^^^^^^^^
  File "/home/airflow/.local/lib/python3.12/site-packages/airflow/utils/session.py", line 97, in wrapper
    return func(*args, session=session, **kwargs)
           ^^^^^^^^^^^^^^^^^^^^^^^^^^^^^^^^^^^^^^
  File "/home/airflow/.local/lib/python3.12/site-packages/airflow/models/taskinstance.py", line 3004, in _run_raw_task
    return _run_raw_task(
           ^^^^^^^^^^^^^^
  File "/home/airflow/.local/lib/python3.12/site-packages/airflow/models/taskinstance.py", line 273, in _run_raw_task
    TaskInstance._execute_task_with_callbacks(
  File "/home/airflow/.local/lib/python3.12/site-packages/airflow/models/taskinstance.py", line 3158, in _execute_task_with_callbacks
    result = self._execute_task(context, task_orig)
             ^^^^^^^^^^^^^^^^^^^^^^^^^^^^^^^^^^^^^^
  File "/home/airflow/.local/lib/python3.12/site-packages/airflow/models/taskinstance.py", line 3182, in _execute_task
    return _execute_task(self, context, task_orig)
           ^^^^^^^^^^^^^^^^^^^^^^^^^^^^^^^^^^^^^^^
  File "/home/airflow/.local/lib/python3.12/site-packages/airflow/models/taskinstance.py", line 767, in _execute_task
    result = _execute_callable(context=context, **execute_callable_kwargs)
             ^^^^^^^^^^^^^^^^^^^^^^^^^^^^^^^^^^^^^^^^^^^^^^^^^^^^^^^^^^^^^
  File "/home/airflow/.local/lib/python3.12/site-packages/airflow/models/taskinstance.py", line 733, in _execute_callable
    return ExecutionCallableRunner(
           ^^^^^^^^^^^^^^^^^^^^^^^^
  File "/home/airflow/.local/lib/python3.12/site-packages/airflow/utils/operator_helpers.py", line 252, in run
    return self.func(*args, **kwargs)
           ^^^^^^^^^^^^^^^^^^^^^^^^^^
  File "/home/airflow/.local/lib/python3.12/site-packages/airflow/models/baseoperator.py", line 406, in wrapper
    return func(self, *args, **kwargs)
           ^^^^^^^^^^^^^^^^^^^^^^^^^^^
  File "/home/airflow/.local/lib/python3.12/site-packages/airflow/operators/python.py", line 238, in execute
    return_value = self.execute_callable()
                   ^^^^^^^^^^^^^^^^^^^^^^^
  File "/home/airflow/.local/lib/python3.12/site-packages/airflow/operators/python.py", line 256, in execute_callable
    return runner.run(*self.op_args, **self.op_kwargs)
           ^^^^^^^^^^^^^^^^^^^^^^^^^^^^^^^^^^^^^^^^^^^
  File "/home/airflow/.local/lib/python3.12/site-packages/airflow/utils/operator_helpers.py", line 252, in run
    return self.func(*args, **kwargs)
           ^^^^^^^^^^^^^^^^^^^^^^^^^^
  File "/opt/airflow/dags/generate_orders_dag.py", line 32, in generate_orders
    cur.execute("SELECT id FROM clean.users;")
psycopg2.errors.UndefinedTable: ОШИБКА:  отношение "clean.users" не существует
LINE 1: SELECT id FROM clean.users;
                       ^

[2025-09-20T19:52:45.635+0000] {local_task_job_runner.py:266} INFO - Task exited with return code 1
[2025-09-20T19:52:45.657+0000] {taskinstance.py:3900} INFO - 0 downstream tasks scheduled from follow-on schedule check
[2025-09-20T19:52:45.661+0000] {local_task_job_runner.py:245} INFO - ::endgroup::
