[2025-09-20T18:54:01.630+0000] {local_task_job_runner.py:120} INFO - ::group::Pre task execution logs
[2025-09-20T18:54:01.670+0000] {taskinstance.py:2076} INFO - Dependencies all met for dep_context=non-requeueable deps ti=<TaskInstance: clean_users_from_lake_dag.load_users_to_postgres manual__2025-09-20T18:53:49.386529+00:00 [queued]>
[2025-09-20T18:54:01.678+0000] {taskinstance.py:2076} INFO - Dependencies all met for dep_context=requeueable deps ti=<TaskInstance: clean_users_from_lake_dag.load_users_to_postgres manual__2025-09-20T18:53:49.386529+00:00 [queued]>
[2025-09-20T18:54:01.679+0000] {taskinstance.py:2306} INFO - Starting attempt 1 of 1
[2025-09-20T18:54:01.690+0000] {taskinstance.py:2330} INFO - Executing <Task(PythonOperator): load_users_to_postgres> on 2025-09-20 18:53:49.386529+00:00
[2025-09-20T18:54:01.699+0000] {standard_task_runner.py:90} INFO - Running: ['airflow', 'tasks', 'run', 'clean_users_from_lake_dag', 'load_users_to_postgres', 'manual__2025-09-20T18:53:49.386529+00:00', '--job-id', '8', '--raw', '--subdir', 'DAGS_FOLDER/clean_users_dag.py', '--cfg-path', '/tmp/tmp7u5c73os']
[2025-09-20T18:54:01.700+0000] {standard_task_runner.py:91} INFO - Job 8: Subtask load_users_to_postgres
[2025-09-20T18:54:01.702+0000] {logging_mixin.py:188} WARNING - /home/airflow/.local/lib/python3.12/site-packages/airflow/task/task_runner/standard_task_runner.py:62 DeprecationWarning: This process (pid=461) is multi-threaded, use of fork() may lead to deadlocks in the child.
[2025-09-20T18:54:01.703+0000] {standard_task_runner.py:64} INFO - Started process 470 to run task
[2025-09-20T18:54:01.767+0000] {task_command.py:426} INFO - Running <TaskInstance: clean_users_from_lake_dag.load_users_to_postgres manual__2025-09-20T18:53:49.386529+00:00 [running]> on host b98534788494
[2025-09-20T18:54:01.867+0000] {taskinstance.py:2648} INFO - Exporting env vars: AIRFLOW_CTX_DAG_OWNER='airflow' AIRFLOW_CTX_DAG_ID='clean_users_from_lake_dag' AIRFLOW_CTX_TASK_ID='load_users_to_postgres' AIRFLOW_CTX_EXECUTION_DATE='2025-09-20T18:53:49.386529+00:00' AIRFLOW_CTX_TRY_NUMBER='1' AIRFLOW_CTX_DAG_RUN_ID='manual__2025-09-20T18:53:49.386529+00:00'
[2025-09-20T18:54:01.868+0000] {taskinstance.py:430} INFO - ::endgroup::
[2025-09-20T18:54:01.899+0000] {taskinstance.py:441} INFO - ::group::Post task execution logs
[2025-09-20T18:54:01.900+0000] {taskinstance.py:2905} ERROR - Task failed with exception
Traceback (most recent call last):
  File "/home/airflow/.local/lib/python3.12/site-packages/airflow/models/taskinstance.py", line 465, in _execute_task
    result = _execute_callable(context=context, **execute_callable_kwargs)
             ^^^^^^^^^^^^^^^^^^^^^^^^^^^^^^^^^^^^^^^^^^^^^^^^^^^^^^^^^^^^^
  File "/home/airflow/.local/lib/python3.12/site-packages/airflow/models/taskinstance.py", line 432, in _execute_callable
    return execute_callable(context=context, **execute_callable_kwargs)
           ^^^^^^^^^^^^^^^^^^^^^^^^^^^^^^^^^^^^^^^^^^^^^^^^^^^^^^^^^^^^
  File "/home/airflow/.local/lib/python3.12/site-packages/airflow/models/baseoperator.py", line 401, in wrapper
    return func(self, *args, **kwargs)
           ^^^^^^^^^^^^^^^^^^^^^^^^^^^
  File "/home/airflow/.local/lib/python3.12/site-packages/airflow/operators/python.py", line 235, in execute
    return_value = self.execute_callable()
                   ^^^^^^^^^^^^^^^^^^^^^^^
  File "/home/airflow/.local/lib/python3.12/site-packages/airflow/operators/python.py", line 252, in execute_callable
    return self.python_callable(*self.op_args, **self.op_kwargs)
           ^^^^^^^^^^^^^^^^^^^^^^^^^^^^^^^^^^^^^^^^^^^^^^^^^^^^^
  File "/opt/airflow/dags/clean_users_dag.py", line 36, in load_task
    load_users(df)
  File "/opt/airflow/src/etl/load.py", line 9, in load_users
    with get_conn() as conn, conn.cursor() as cur:
         ^^^^^^^^^^
  File "/opt/airflow/src/db/db_connection.py", line 5, in get_conn
    return psycopg2.connect(
           ^^^^^^^^^^^^^^^^^
  File "/home/airflow/.local/lib/python3.12/site-packages/psycopg2/__init__.py", line 122, in connect
    conn = _connect(dsn, connection_factory=connection_factory, **kwasync)
           ^^^^^^^^^^^^^^^^^^^^^^^^^^^^^^^^^^^^^^^^^^^^^^^^^^^^^^^^^^^^^^^
psycopg2.OperationalError: connection to server on socket "/var/run/postgresql/.s.PGSQL.5432" failed: No such file or directory
	Is the server running locally and accepting connections on that socket?

[2025-09-20T18:54:01.929+0000] {taskinstance.py:1206} INFO - Marking task as FAILED. dag_id=clean_users_from_lake_dag, task_id=load_users_to_postgres, run_id=manual__2025-09-20T18:53:49.386529+00:00, execution_date=20250920T185349, start_date=20250920T185401, end_date=20250920T185401
[2025-09-20T18:54:01.942+0000] {standard_task_runner.py:110} ERROR - Failed to execute job 8 for task load_users_to_postgres (connection to server on socket "/var/run/postgresql/.s.PGSQL.5432" failed: No such file or directory
	Is the server running locally and accepting connections on that socket?
; 470)
[2025-09-20T18:54:01.957+0000] {local_task_job_runner.py:243} INFO - Task exited with return code 1
[2025-09-20T18:54:01.977+0000] {taskinstance.py:3503} INFO - 0 downstream tasks scheduled from follow-on schedule check
[2025-09-20T18:54:01.980+0000] {local_task_job_runner.py:222} INFO - ::endgroup::
